Workbook

Sheet incubationInfo
E1: Pre-flush info | G1: Treatment info | J1: Spike info
A2: incubationID | B2: incubationType | C2: sourceMaterial | D2: subSiteID | E2: preFlushMatrix | F2: startTimeAndDatePreFlushing | G2: treatment | H2: flushMatrix | I2: startTimeAndDateFlushing | J2: spikeID | K2: startDate | L2: startTime | N2: Notes
A3: PCaMM_inc_001 | B3: PCaMM trial runs - HPG-Hg(II) interactions | C3: sediment from arboretum | D3: N/A | E3: purged and filtered surface water from arboretum | F3: 45433.472 | G3: HPG- | H3: purged and filtered surface water from arboretum | I3: 45433.472 | K3: 2024-05-21 | L3: 16:20
A4: PCaMM_inc_002 | B4: PCaMM trial runs - HPG-Hg(II) interactions | C4: sediment from arboretum | D4: N/A | E4: purged and filtered surface water from arboretum | F4: 45433.472 | G4: HPG+ | H4: purged and filtered surface water from arboretum with HPG added to final concentration of 50 µM | I4: 45433.472 | K4: 2024-05-21 | L4: 16:30
A5: PCaMM_inc_003 | B5: PCaMM trial runs - HPG-Hg(II) interactions | C5: sediment from arboretum | D5: N/A | E5: purged and filtered surface water from arboretum | F5: 45433.472 | G5: HPG+ | H5: purged and filtered surface water from arboretum with HPG added to final concentration of 50 µM | I5: 45433.472 | K5: 2024-05-21 | L5: 16:40
A6: PCaMM_inc_004 | B6: PCaMM trial runs - HPG-Hg(II) interactions | C6: sediment from arboretum | D6: N/A | E6: purged and filtered surface water from arboretum | F6: 45433.472 | G6: HPG- | H6: purged and filtered surface water from arboretum | I6: 45433.472 | K6: 2024-05-21 | L6: 16:50
A7: PCaMM_inc_005 | B7: PCaMM trial runs - Timing and concentration for HPG incorporation | C7: AK23_MSC_060 | D7: SitukuyokR_BP_04 | E7: 80 mL of permafrost DOM from AK24_MSC_046 | F7: 45440.497 | G7: 50µM HPG+ and Hg(II)-, 36 hr | H7: 50 mL of pre-flush matrix was removed from the bag, then 70 mL of fresh filtered and anoxic permafrost DOM from AK24_MSC_046 was added. Added 654 µL of 15.28 mM HPG to bag. | I7: 45442.069 | J7: PCaMM_spike_002 | K7: 2024-05-30 | L7: 2:25
A8: PCaMM_inc_006 | B8: PCaMM trial runs - Timing and concentration for HPG incorporation | C8: AK23_MSC_050 | D8: SitukuyokR_BP_04 | E8: 80 mL of permafrost DOM from AK24_MSC_046 | F8: 45440.497 | G8: HPG- and Hg(II)+, 36 hr | H8: 50 mL of pre-flush matrix was removed from the bag, then 70 mL of fresh filtered and anoxic permafrost DOM from AK24_MSC_046 was added. Added no HPG | I8: 45442.069 | J8: PCaMM_spike_002 | K8: 2024-05-30 | L8: 0.00
A9: PCaMM_inc_007 | B9: PCaMM trial runs - Timing and concentration for HPG incorporation | C9: AK23_MSC_054 | D9: SitukuyokR_BP_04 | E9: 80 mL of permafrost DOM from AK24_MSC_046 | F9: 45440.497 | G9: 10µM HPG+ and Hg(II)+, 36 hr | H9: 50 mL of pre-flush matrix was removed from the bag, then 70 mL of fresh filtered and anoxic permafrost DOM from AK24_MSC_046 was added. Added 130 µL of 15.28 mM HPG to bag. | I9: 45442.069 | J9: PCaMM_spike_002 | K9: 2024-05-30 | L9: 2:35
A10: PCaMM_inc_008 | B10: PCaMM trial runs - Timing and concentration for HPG incorporation | C10: AK23_MSC_057 | D10: SitukuyokR_BP_04 | E10: 80 mL of permafrost DOM from AK24_MSC_046 | F10: 45440.497 | G10: 10µM HPG+ and Hg(II)+, 12 hr | H10: 50 mL of pre-flush matrix was removed from the bag, then 70 mL of fresh filtered and anoxic permafrost DOM from AK24_MSC_046 was added. Added 130 µL of 15.28 mM HPG to bag. | I10: 45442.069 | J10: PCaMM_spike_002 | K10: 2024-05-30 | L10: 2:40
A11: PCaMM_inc_009 | B11: PCaMM trial runs - Timing and concentration for HPG incorporation | C11: AK23_MSC_058 | D11: SitukuyokR_BP_04 | E11: 80 mL of permafrost DOM from AK24_MSC_046 | F11: 45440.497 | G11: 50µM HPG+ and Hg(II)+, 12 hr | H11: 50 mL of pre-flush matrix was removed from the bag, then 70 mL of fresh filtered and anoxic permafrost DOM from AK24_MSC_046 was added. Added 654 µL of 15.28 mM HPG to bag. | I11: 45442.069 | J11: PCaMM_spike_002 | K11: 2024-05-30 | L11: 2:45
A12: PCaMM_inc_010 | B12: PCaMM trial runs - Timing and concentration for HPG incorporation | C12: AK23_MSC_059 | D12: SitukuyokR_BP_04 | E12: 80 mL of permafrost DOM from AK24_MSC_046 | F12: 45440.497 | G12: 50µM HPG+ and Hg(II)+, 36 hr | H12: Bag had run almost dry during pre-flush, but still had 20 mL in it. Added 10 mL from the pre-flush matrix from PCaMM_inc_009, then 70 mL of fresh filtered and anoxic permafrost DOM from AK24_MSC_046 was added. Added 654 µL of 15.28 mM HPG to bag. | I12: 45442.069 | J12: PCaMM_spike_002 | K12: 2024-05-30 | L12: 2:50

Sheet containerInfo_Hg
C1: Collection info | G1: Freeze-dry info
A2: containerID | B2: incubationID | C2: dateKilled | D2: timeKilled | E2: depth_cm | F2: sideOfIncubation | G2: Tare | H2: massWithWetSample | I2: dateFreezeDried | J2: massWithDriedSample
A3: PCaMM_SCHM_001 | B3: PCaMM_inc_001 | C3: 2024-05-22 | D3: 11:40 | E3: 1-3 | G3: 5.25 | H3: 23.99
A4: PCaMM_SCHM_002 | B4: PCaMM_inc_001 | C4: 2024-05-22 | D4: 11:41 | E4: 1-3 | G4: 5.24 | H4: 23.03
A5: PCaMM_SCHM_003 | B5: PCaMM_inc_001 | C5: 2024-05-22 | D5: 11:42 | E5: 3-6 | G5: 5.24 | H5: 17.62
A6: PCaMM_SCHM_004 | B6: PCaMM_inc_001 | C6: 2024-05-22 | D6: 11:43 | E6: 3-6 | G6: 5.22 | H6: 18.05
A7: PCaMM_SCHM_005 | B7: PCaMM_inc_002 | C7: 2024-05-22 | D7: 11:56 | E7: 1-3 | F7: Left | G7: 5.23 | H7: 25.26
A8: PCaMM_SCHM_006 | B8: PCaMM_inc_002 | C8: 2024-05-22 | D8: 11:57 | E8: 1-3 | F8: Right | G8: 5.23 | H8: 21.19
A9: PCaMM_SCHM_007 | B9: PCaMM_inc_002 | C9: 2024-05-22 | D9: 11:58 | E9: 3-5 | F9: Left | G9: 5.24 | H9: 31.43
A10: PCaMM_SCHM_008 | B10: PCaMM_inc_002 | C10: 2024-05-22 | D10: 11:59 | E10: 3-5 | F10: Right | G10: 5.24 | H10: 25.65
A11: PCaMM_SCHM_009 | B11: PCaMM_inc_003 | C11: 2024-05-23 | D11: 00:05 | E11: 1-3 | F11: Left | G11: 5.25 | H11: 25.09
A12: PCaMM_SCHM_010 | B12: PCaMM_inc_003 | C12: 2024-05-23 | D12: 00:06 | E12: 1-3 | F12: Right | G12: 5.21 | H12: 27.45
A13: PCaMM_SCHM_011 | B13: PCaMM_inc_003 | C13: 2024-05-23 | D13: 00:07 | E13: 3-5 | F13: Left | G13: 5.22 | H13: 32.5
A14: PCaMM_SCHM_012 | B14: PCaMM_inc_003 | C14: 2024-05-23 | D14: 00:08 | E14: 3-5 | F14: Right | G14: 5.21 | H14: 27.34
A15: PCaMM_SCHM_013 | B15: PCaMM_inc_004 | C15: 2024-05-23 | D15: 00:13 | E15: 1-3 | F15: Left | G15: 5.2 | H15: 25.97
A16: PCaMM_SCHM_014 | B16: PCaMM_inc_004 | C16: 2024-05-23 | D16: 00:14 | E16: 1-3 | F16: Right | G16: 5.19 | H16: 23.83
A17: PCaMM_SCHM_015 | B17: PCaMM_inc_004 | C17: 2024-05-23 | D17: 00:15 | E17: 3-5 | F17: Left | G17: 5.2 | H17: 35.04
A18: PCaMM_SCHM_016 | B18: PCaMM_inc_004 | C18: 2024-05-23 | D18: 00:16 | E18: 3-5 | F18: Right | G18: 5.23 | H18: 25.3
A19: PCaMM_SCHM_017 | B19: PCaMM_inc_008 | C19: 2024-05-30 | D19: 14:07 | E19: 1-3 | F19: Right | G19: 5.22 | H19: 20.5 | I19: 2024-06-11
A20: PCaMM_SCHM_018 | B20: PCaMM_inc_008 | C20: 2024-05-30 | D20: 14:07 | E20: 1-3 | F20: Left | G20: 5.19 | H20: 21.78
A21: PCaMM_SCHM_019 | B21: PCaMM_inc_008 | C21: 2024-05-30 | D21: 14:07 | E21: 3-5 | F21: Right | G21: 5.23 | H21: 25.05 | I21: 2024-06-11
A22: PCaMM_SCHM_020 | B22: PCaMM_inc_008 | C22: 2024-05-30 | D22: 14:07 | E22: 3-5 | F22: Left | G22: 5.27 | H22: 26.27
A23: PCaMM_SCHM_021 | B23: PCaMM_inc_009 | C23: 2024-05-30 | D23: 14:38 | E23: 1-3 | F23: Right | G23: 5.21 | H23: 22.47
A24: PCaMM_SCHM_022 | B24: PCaMM_inc_009 | C24: 2024-05-30 | D24: 14:38 | E24: 1-3 | F24: Left | G24: 5.21 | H24: 23.41
A25: PCaMM_SCHM_023 | B25: PCaMM_inc_009 | C25: 2024-05-30 | D25: 14:38 | E25: 3-5 | F25: Right | G25: 5.2 | H25: 22.82
A26: PCaMM_SCHM_024 | B26: PCaMM_inc_009 | C26: 2024-05-30 | D26: 14:38 | E26: 3-5 | F26: Left | G26: 5.2 | H26: 20.23 | I26: 2024-06-11
A27: PCaMM_SCHM_025 | B27: PCaMM_inc_005 | C27: 2024-05-31 | D27: 13:30 | E27: 1-3 | F27: Right | G27: 5.34 | H27: 21.02 | I27: 2024-06-11
A28: PCaMM_SCHM_026 | B28: PCaMM_inc_005 | C28: 2024-05-31 | D28: 13:30 | E28: 1-3 | F28: Left | G28: 5.24 | H28: 19 | I28: 2024-06-11
A29: PCaMM_SCHM_027 | B29: PCaMM_inc_005 | C29: 2024-05-31 | D29: 13:30 | E29: 3-5 | F29: Right | G29: 5.23 | H29: 28.07 | I29: 2024-06-11
A30: PCaMM_SCHM_028 | B30: PCaMM_inc_005 | C30: 2024-05-31 | D30: 13:30 | E30: 3-5 | F30: Left | G30: 5.22 | H30: 26.8
A31: PCaMM_SCHM_029 | B31: PCaMM_inc_006 | C31: 2024-05-31 | D31: 23:00 | E31: 1-3 | F31: Right | G31: 5.23 | H31: 19.98 | I31: 2024-06-11
A32: PCaMM_SCHM_030 | B32: PCaMM_inc_006 | C32: 2024-05-31 | D32: 23:00 | E32: 1-3 | F32: Left | G32: 5.22 | H32: 20.24 | I32: 2024-06-11
A33: PCaMM_SCHM_031 | B33: PCaMM_inc_006 | C33: 2024-05-31 | D33: 23:00 | E33: 3-5 | F33: Right | G33: 5.23 | H33: 17.2 | I33: 2024-06-11
A34: PCaMM_SCHM_032 | B34: PCaMM_inc_006 | C34: 2024-05-31 | D34: 23:00 | E34: 3-5 | F34: Left | G34: 5.23 | H34: 22.28
A35: PCaMM_SCHM_033 | B35: PCaMM_inc_007 | C35: 2024-05-31 | D35: 13:05 | E35: 1-3 | F35: Right | G35: 5.26 | H35: 23.17 | I35: 2024-06-11
A36: PCaMM_SCHM_034 | B36: PCaMM_inc_007 | C36: 2024-05-31 | D36: 13:05 | E36: 1-3 | F36: Left | G36: 5.23 | H36: 17.42 | I36: 2024-06-11
A37: PCaMM_SCHM_035 | B37: PCaMM_inc_007 | C37: 2024-05-31 | D37: 13:05 | E37: 3-5 | F37: Right | G37: 5.28 | H37: 31.3
A38: PCaMM_SCHM_036 | B38: PCaMM_inc_007 | C38: 2024-05-31 | D38: 13:05 | E38: 3-5 | F38: Left | G38: 5.25 | H38: 22.78
A39: PCaMM_SCHM_037 | B39: PCaMM_inc_010 | C39: 2024-05-31 | D39: 12:10 | E39: 1-3 | F39: Right | G39: 5.23 | H39: 28.6 | I39: 2024-06-11
A40: PCaMM_SCHM_038 | B40: PCaMM_inc_010 | C40: 2024-05-31 | D40: 12:10 | E40: 1-3 | F40: Left | G40: 5.26 | H40: 25.52
...

Sheet containerInfo_BONCAT
C1: Collection info
A2: containerID | B2: incubationID | C2: dateKilled | D2: timeKilled | E2: depth_cm | F2: sideOfIncubation | G2: Notes
A3: PM24_BCT_001 | B3: PCaMM_inc_008 | C3: 2024-05-30 | D3: 14:07 | E3: 1-3 | F3: Right | G3: Added 100 µL of 60% glycerol to <1 mL homogenized sediment
A4: PM24_BCT_002 | B4: PCaMM_inc_008 | C4: 2024-05-30 | D4: 14:07 | E4: 1-3 | F4: Right | G4: Added 100 µL of 60% glycerol to <1 mL homogenized sediment
A5: PM24_BCT_003 | B5: PCaMM_inc_008 | C5: 2024-05-30 | D5: 14:07 | E5: 1-3 | F5: Left | G5: Added 100 µL of 60% glycerol to <1 mL homogenized sediment
A6: PM24_BCT_004 | B6: PCaMM_inc_008 | C6: 2024-05-30 | D6: 14:07 | E6: 1-3 | F6: Left | G6: Added 100 µL of 60% glycerol to <1 mL homogenized sediment
A7: PM24_BCT_005 | B7: PCaMM_inc_008 | C7: 2024-05-30 | D7: 14:07 | E7: 3-5 | F7: Right | G7: Added 100 µL of 60% glycerol to <1 mL homogenized sediment
A8: PM24_BCT_006 | B8: PCaMM_inc_008 | C8: 2024-05-30 | D8: 14:07 | E8: 3-5 | F8: Right | G8: Added 100 µL of 60% glycerol to <1 mL homogenized sediment
A9: PM24_BCT_007 | B9: PCaMM_inc_008 | C9: 2024-05-30 | D9: 14:07 | E9: 3-5 | F9: Left | G9: Added 100 µL of 60% glycerol to <1 mL homogenized sediment
A10: PM24_BCT_008 | B10: PCaMM_inc_008 | C10: 2024-05-30 | D10: 14:07 | E10: 3-5 | F10: Left | G10: Added 100 µL of 60% glycerol to <1 mL homogenized sediment
A11: PM24_BCT_009 | B11: PCaMM_inc_009 | C11: 2024-05-30 | D11: 14:38 | E11: 1-3 | F11: Right | G11: Added 100 µL of 60% glycerol to <1 mL homogenized sediment
A12: PM24_BCT_010 | B12: PCaMM_inc_009 | C12: 2024-05-30 | D12: 14:38 | E12: 1-3 | F12: Right | G12: Added 100 µL of 60% glycerol to <1 mL homogenized sediment
A13: PM24_BCT_011 | B13: PCaMM_inc_009 | C13: 2024-05-30 | D13: 14:38 | E13: 1-3 | F13: Left | G13: Added 100 µL of 60% glycerol to <1 mL homogenized sediment
... A50: PM24_BCT_048 | B50: PCaMM_inc_007 | C50: 2024-05-31 | D50: 13:05 | E50: 3-5 | F50: Left | G50: Added 100 µL of 60% glycerol to <1 mL homogenized sediment
A51: PM24_BCT_049 | B51: N/A | C51: 2024-06-10 | G51: Collected from core AK23_MSC_058, just below the incubation material
A52: PM24_BCT_050 | B52: N/A | C52: 2024-06-10 | G52: Collected from core AK23_MSC_058, just below the incubation material
A53: PM24_BCT_051 | B53: N/A | C53: 2024-06-10 | G53: Collected from core AK23_MSC_058, just below the incubation material
A54: PM24_BCT_052 | B54: N/A | C54: 2024-06-10 | G54: Collected from core AK23_MSC_058, just below the incubation material
A55: PM24_BCT_053 | B55: N/A | C55: 2024-06-10 | G55: Collected from core AK23_MSC_059, just below the incubation material
A56: PM24_BCT_054 | B56: N/A | C56: 2024-06-10 | G56: Collected from core AK23_MSC_059, just below the incubation material
A57: PM24_BCT_055 | B57: N/A | C57: 2024-06-10 | G57: Collected from core AK23_MSC_059, just below the incubation material
A58: PM24_BCT_056 | B58: N/A | C58: 2024-06-10 | G58: Collected from core AK23_MSC_059, just below the incubation material

Sheet containerInfo_other
A1: containerID | B1: incubationID | C1: dateKilled | D1: timeKilled | E1: Volume (ml) | F1: Preservation | G1: Notes
A2: PCaMM_PW_001 | B2: PCaMM_inc_001 | C2: 2024-05-22 | D2: 11:25 | E2: 50 | F2: Acidified to 1% HCl | G2: Taken from outflow
A3: PCaMM_PW_002 | B3: PCaMM_inc_002 | C3: 2024-05-22 | D3: 11:26 | E3: 50 | F3: Acidified to 1% HCl | G3: Taken from outflow
A4: PCaMM_PW_003 | B4: PCaMM_inc_003 | C4: 2024-05-22 | D4: 11:27 | E4: 50 | F4: Acidified to 1% HCl | G4: Taken from outflow
A5: PCaMM_PW_004 | B5: PCaMM_inc_004 | C5: 2024-05-22 | D5: 11:28 | E5: 50 | F5: Acidified to 1% HCl | G5: Taken from outflow
A6: PCaMM_PW_005 | B6: PCaMM_inc_001 | C6: 2024-05-22 | D6: 11:29 | E6: 50 | F6: Acidified to 1% HCl | G6: Taken from bag
A7: PCaMM_PW_006 | B7: PCaMM_inc_002 | C7: 2024-05-22 | D7: 11:30 | E7: 50 | F7: Acidified to 1% HCl | G7: Taken from bag
A8: PCaMM_PW_007 | B8: PCaMM_inc_003 | C8: 2024-05-22 | D8: 11:31 | E8: 50 | F8: Acidified to 1% HCl | G8: Taken from bag
A9: PCaMM_PW_008 | B9: PCaMM_inc_004 | C9: 2024-05-22 | D9: 11:32 | E9: 50 | F9: Acidified to 1% HCl | G9: Taken from bag
A10: PCaMM24_DOC_002 | B10: PCaMM_inc_009 | C10: 2024-05-30 | D10: 14:07 | E10: 10 | F10: Filtered through 0.2 µm filter, stored in fridge with no headspace
A11: PCaMM24_DOC_003 | B11: PCaMM_inc_010 | C11: 2024-05-31 | D11: 12:10 | E11: 10 | F11: Filtered through 0.2 µm filter, stored in fridge with no headspace
A12: PCaMM24_DOC_004 | B12: PCaMM_inc_005 | C12: 2024-05-31 | D12: 13:30 | E12: 10 | F12: Filtered through 0.2 µm filter, stored in fridge with no headspace
A13: PCaMM24_DOC_005 | B13: PCaMM_inc_006 | C13: 2024-05-31 | D13: 12:50 | E13: 10 | F13: Filtered through 0.2 µm filter, stored in fridge with no headspace
A14: PCaMM24_DOC_006 | B14: PCaMM_inc_007 | C14: 2024-05-31 | D14: 13:05 | E14: 10 | F14: Filtered through 0.2 µm filter, stored in fridge with no headspace
A15: PCaMM24_FILT_001 | B15: PCaMM_inc_009 | C15: 2024-05-30 | D15: 14:07 | E15: 40 | F15: Filtered through 0.2 µm filter, acidified to 1% HCl
A16: PCaMM24_FILT_003 | B16: PCaMM_inc_010 | C16: 2024-05-31 | D16: 12:10 | E16: 22 | F16: Filtered through 0.2 µm filter, acidified to 1% HCl
A17: PCaMM24_FILT_004 | B17: PCaMM_inc_005 | C17: 2024-05-31 | D17: 13:30 | E17: 30 | F17: Filtered through 0.2 µm filter, acidified to 1% HCl
A18: PCaMM24_FILT_005 | B18: PCaMM_inc_006 | C18: 2024-05-31 | D18: 12:50 | E18: 28 | F18: Filtered through 0.2 µm filter, acidified to 1% HCl
A19: PCaMM24_FILT_006 | B19: PCaMM_inc_007 | C19: 2024-05-31 | D19: 13:05 | E19: 22 | F19: Filtered through 0.2 µm filter, acidified to 1% HCl
A20: PCaMM24_FRZN_002 | B20: PCaMM_inc_009 | C20: 2024-05-30 | D20: 14:07 | E20: 20 | F20: Filtered through 0.2 µm filter, frozen at -20˚C
A21: PCaMM24_FRZN_003 | B21: PCaMM_inc_010 | C21: 2024-05-31 | D21: 12:10 | E21: 20 | F21: Filtered through 0.2 µm filter, frozen at -20˚C
A22: PCaMM24_FRZN_004 | B22: PCaMM_inc_005 | C22: 2024-05-31 | D22: 13:30 | E22: 20 | F22: Filtered through 0.2 µm filter, frozen at -20˚C
A23: PCaMM24_FRZN_005 | B23: PCaMM_inc_006 | C23: 2024-05-31 | D23: 12:50 | E23: 18 | F23: Filtered through 0.2 µm filter, frozen at -20˚C
A24: PCaMM24_FRZN_006 | B24: PCaMM_inc_007 | C24: 2024-05-31 | D24: 13:05 | E24: 16 | F24: Filtered through 0.2 µm filter, frozen at -20˚C

Sheet SpikeInfo
A1: spikeID | B1: datePrepped | C1: timePrepped | D1: Recipe | E1: Expected concentration of Hg(II) (ng/ml)
A2: PCaMM_spike_001
A3: PCaMM_spike_002 | B3: 45441 | C3: 0.6875 | D3: 39.7 mL of filtered anoxic permafrost DOM | E3: 225

Sheet SpikePreservation
A1: preservedSpikeID | B1: spikeID | C1: dateKilled | D1: timeKilled | E1: Notes
B2: PCaMM_spike_001
A3: PCaMM_spike_002_t0 | B3: PCaMM_spike_002 | C3: 2024-05-30 | D3: 2:40 | E3: Preserved after spiking samples. 5 mL.
A4: PCaMM_spike_002_t2 | B4: PCaMM_spike_002 | C4: 2024-05-31 | D4: 11:50 | E4: Preserved along with 36 hr incubations. 5 mL.

Sheet printed_sheet
B1: Incubation ID:
B2: Date: | D2: Time:
B4: Container ID | D4: Volume | E4: Preservation | F4: Notes
A5: Acidified sample:
A6: Frozen sample:
A7: Filtered sample:
B9: Hg container IDs | D9: BONCAT container IDs | F9: Notes
A10: Top right:
A11: Top left:
A12: Bottom right:
A13: Bottom left:
B15: Incubation ID:
B16: Date: | D16: Time:
B18: Container ID | D18: Volume | E18: Preservation | F18: Notes
A19: Acidified sample:
A20: Frozen sample:
A21: Filtered sample:
B23: Hg container IDs | D23: BONCAT container IDs | F23: Notes
A24: Top right:
A25: Top left:
A26: Bottom right:
A27: Bottom left:

Sheet EXTERNAL_info_for_danielle
A1: containerID | B1: Incubation ID | C1: Location within core | D1: Incubation conditions
A2: PM24_BCT_001 | B2: =VLOOKUP(A2,containerInfo_BONCAT!$A$3:$B$60,2,FALSE) -> PCaMM_inc_008 | C2: =_xlfn.CONCAT(VLOOKUP(A2,containerInfo_BONCAT!$A$3:$T$60,5,FALSE),"cm, ",VLOOKUP(A2,containerInfo_BONCAT!$A$3:$T$60,6,FALSE), " side") -> 1-3cm, Right side | D2: =VLOOKUP(B2,incubationInfo!$A$3:$G$12,7,FALSE) -> 10µM HPG+ and Hg(II)+, 12 hr
A3: PM24_BCT_002 | B3: =VLOOKUP(A3,containerInfo_BONCAT!$A$3:$B$60,2,FALSE) -> PCaMM_inc_008 | C3: =_xlfn.CONCAT(VLOOKUP(A3,containerInfo_BONCAT!$A$3:$T$60,5,FALSE),"cm, ",VLOOKUP(A3,containerInfo_BONCAT!$A$3:$T$60,6,FALSE), " side") -> 1-3cm, Right side | D3: =VLOOKUP(B3,incubationInfo!$A$3:$G$12,7,FALSE) -> 10µM HPG+ and Hg(II)+, 12 hr
A4: PM24_BCT_003 | B4: =VLOOKUP(A4,containerInfo_BONCAT!$A$3:$B$60,2,FALSE) -> PCaMM_inc_008 | C4: =_xlfn.CONCAT(VLOOKUP(A4,containerInfo_BONCAT!$A$3:$T$60,5,FALSE),"cm, ",VLOOKUP(A4,containerInfo_BONCAT!$A$3:$T$60,6,FALSE), " side") -> 1-3cm, Left side | D4: =VLOOKUP(B4,incubationInfo!$A$3:$G$12,7,FALSE) -> 10µM HPG+ and Hg(II)+, 12 hr
A5: PM24_BCT_004 | B5: =VLOOKUP(A5,containerInfo_BONCAT!$A$3:$B$60,2,FALSE) -> PCaMM_inc_008 | C5: =_xlfn.CONCAT(VLOOKUP(A5,containerInfo_BONCAT!$A$3:$T$60,5,FALSE),"cm, ",VLOOKUP(A5,containerInfo_BONCAT!$A$3:$T$60,6,FALSE), " side") -> 1-3cm, Left side | D5: =VLOOKUP(B5,incubationInfo!$A$3:$G$12,7,FALSE) -> 10µM HPG+ and Hg(II)+, 12 hr
A6: PM24_BCT_005 | B6: =VLOOKUP(A6,containerInfo_BONCAT!$A$3:$B$60,2,FALSE) -> PCaMM_inc_008 | C6: =_xlfn.CONCAT(VLOOKUP(A6,containerInfo_BONCAT!$A$3:$T$60,5,FALSE),"cm, ",VLOOKUP(A6,containerInfo_BONCAT!$A$3:$T$60,6,FALSE), " side") -> 3-5cm, Right side | D6: =VLOOKUP(B6,incubationInfo!$A$3:$G$12,7,FALSE) -> 10µM HPG+ and Hg(II)+, 12 hr
A7: PM24_BCT_006 | B7: =VLOOKUP(A7,containerInfo_BONCAT!$A$3:$B$60,2,FALSE) -> PCaMM_inc_008 | C7: =_xlfn.CONCAT(VLOOKUP(A7,containerInfo_BONCAT!$A$3:$T$60,5,FALSE),"cm, ",VLOOKUP(A7,containerInfo_BONCAT!$A$3:$T$60,6,FALSE), " side") -> 3-5cm, Right side | D7: =VLOOKUP(B7,incubationInfo!$A$3:$G$12,7,FALSE) -> 10µM HPG+ and Hg(II)+, 12 hr
A8: PM24_BCT_007 | B8: =VLOOKUP(A8,containerInfo_BONCAT!$A$3:$B$60,2,FALSE) -> PCaMM_inc_008 | C8: =_xlfn.CONCAT(VLOOKUP(A8,containerInfo_BONCAT!$A$3:$T$60,5,FALSE),"cm, ",VLOOKUP(A8,containerInfo_BONCAT!$A$3:$T$60,6,FALSE), " side") -> 3-5cm, Left side | D8: =VLOOKUP(B8,incubationInfo!$A$3:$G$12,7,FALSE) -> 10µM HPG+ and Hg(II)+, 12 hr
A9: PM24_BCT_008 | B9: =VLOOKUP(A9,containerInfo_BONCAT!$A$3:$B$60,2,FALSE) -> PCaMM_inc_008 | C9: =_xlfn.CONCAT(VLOOKUP(A9,containerInfo_BONCAT!$A$3:$T$60,5,FALSE),"cm, ",VLOOKUP(A9,containerInfo_BONCAT!$A$3:$T$60,6,FALSE), " side") -> 3-5cm, Left side | D9: =VLOOKUP(B9,incubationInfo!$A$3:$G$12,7,FALSE) -> 10µM HPG+ and Hg(II)+, 12 hr
A10: PM24_BCT_009 | B10: =VLOOKUP(A10,containerInfo_BONCAT!$A$3:$B$60,2,FALSE) -> PCaMM_inc_009 | C10: =_xlfn.CONCAT(VLOOKUP(A10,containerInfo_BONCAT!$A$3:$T$60,5,FALSE),"cm, ",VLOOKUP(A10,containerInfo_BONCAT!$A$3:$T$60,6,FALSE), " side") -> 1-3cm, Right side | D10: =VLOOKUP(B10,incubationInfo!$A$3:$G$12,7,FALSE) -> 50µM HPG+ and Hg(II)+, 12 hr
A11: PM24_BCT_010 | B11: =VLOOKUP(A11,containerInfo_BONCAT!$A$3:$B$60,2,FALSE) -> PCaMM_inc_009 | C11: =_xlfn.CONCAT(VLOOKUP(A11,containerInfo_BONCAT!$A$3:$T$60,5,FALSE),"cm, ",VLOOKUP(A11,containerInfo_BONCAT!$A$3:$T$60,6,FALSE), " side") -> 1-3cm, Right side | D11: =VLOOKUP(B11,incubationInfo!$A$3:$G$12,7,FALSE) -> 50µM HPG+ and Hg(II)+, 12 hr
A12: PM24_BCT_011 | B12: =VLOOKUP(A12,containerInfo_BONCAT!$A$3:$B$60,2,FALSE) -> PCaMM_inc_009 | C12: =_xlfn.CONCAT(VLOOKUP(A12,containerInfo_BONCAT!$A$3:$T$60,5,FALSE),"cm, ",VLOOKUP(A12,containerInfo_BONCAT!$A$3:$T$60,6,FALSE), " side") -> 1-3cm, Left side | D12: =VLOOKUP(B12,incubationInfo!$A$3:$G$12,7,FALSE) -> 50µM HPG+ and Hg(II)+, 12 hr
A13: PM24_BCT_012 | B13: =VLOOKUP(A13,containerInfo_BONCAT!$A$3:$B$60,2,FALSE) -> PCaMM_inc_009 | C13: =_xlfn.CONCAT(VLOOKUP(A13,containerInfo_BONCAT!$A$3:$T$60,5,FALSE),"cm, ",VLOOKUP(A13,containerInfo_BONCAT!$A$3:$T$60,6,FALSE), " side") -> 1-3cm, Left side | D13: =VLOOKUP(B13,incubationInfo!$A$3:$G$12,7,FALSE) -> 50µM HPG+ and Hg(II)+, 12 hr
... A49: PM24_BCT_048 | B49: =VLOOKUP(A49,containerInfo_BONCAT!$A$3:$B$60,2,FALSE) -> PCaMM_inc_007 | C49: =_xlfn.CONCAT(VLOOKUP(A49,containerInfo_BONCAT!$A$3:$T$60,5,FALSE),"cm, ",VLOOKUP(A49,containerInfo_BONCAT!$A$3:$T$60,6,FALSE), " side") -> 3-5cm, Left side | D49: =VLOOKUP(B49,incubationInfo!$A$3:$G$12,7,FALSE) -> 10µM HPG+ and Hg(II)+, 36 hr
A50: PM24_BCT_049 | B50: =VLOOKUP(A50,containerInfo_BONCAT!$A$3:$B$60,2,FALSE) -> N/A | C50: N/A | D50: No HPG added. Collected from the core used for PCaMM_inc_009
A51: PM24_BCT_050 | B51: =VLOOKUP(A51,containerInfo_BONCAT!$A$3:$B$60,2,FALSE) -> N/A | C51: N/A | D51: No HPG added. Collected from the core used for PCaMM_inc_009
A52: PM24_BCT_051 | B52: =VLOOKUP(A52,containerInfo_BONCAT!$A$3:$B$60,2,FALSE) -> N/A | C52: N/A | D52: No HPG added. Collected from the core used for PCaMM_inc_009
A53: PM24_BCT_052 | B53: =VLOOKUP(A53,containerInfo_BONCAT!$A$3:$B$60,2,FALSE) -> N/A | C53: N/A | D53: No HPG added. Collected from the core used for PCaMM_inc_009
A54: PM24_BCT_053 | B54: =VLOOKUP(A54,containerInfo_BONCAT!$A$3:$B$60,2,FALSE) -> N/A | C54: N/A | D54: No HPG added. Collected from the core used for PCaMM_inc_010
A55: PM24_BCT_054 | B55: =VLOOKUP(A55,containerInfo_BONCAT!$A$3:$B$60,2,FALSE) -> N/A | C55: N/A | D55: No HPG added. Collected from the core used for PCaMM_inc_010
A56: PM24_BCT_055 | B56: =VLOOKUP(A56,containerInfo_BONCAT!$A$3:$B$60,2,FALSE) -> N/A | C56: N/A | D56: No HPG added. Collected from the core used for PCaMM_inc_010
A57: PM24_BCT_056 | B57: =VLOOKUP(A57,containerInfo_BONCAT!$A$3:$B$60,2,FALSE) -> N/A | C57: N/A | D57: No HPG added. Collected from the core used for PCaMM_inc_010
